Workbook

Sheet Tableau_de_bord
B2: DealPME : tableau de bord du projet
B3: Toutes les valeurs de cette page sont calculées. Pour mettre à jour le projet, modifier uniquement l'onglet Taches (statuts, % saisi, dates) et les onglets Jalons, Risques, Decisions.
B4: Date du jour | C4: =TODAY() | E4: Jours avant la démonstration V1 | G4: =Versions!E6-TODAY() | I4: Périmètre cible | J4: Cahier des charges v0 + Référentiel P04-P25
B6: Avancement global | D6: Charge totale (j/p) | F6: Charge réalisée (j/p) | H6: Charge totale (sem.-pers.) | J6: Tâches | L6: Faites
B7: =Modules!I26 | D7: =Modules!G26 | F7: =Modules!H26 | H7: =Modules!G26/5 | J7: =Modules!J26 | L7: =Modules!K26
B9: En cours | D9: Bloquées | F9: En retard | H9: Risques critiques ou élevés ouverts | J9: Décisions ouvertes | L9: Jalons dépassés
B10: =Modules!L26 | D10: =Modules!M26 | F10: =Modules!N26 | H10: =COUNTIFS(Risques!$H$6:$H$68,"Critique",Risques!$L$6:$L$68,"<>Clos")+COUNTIFS(Risques!$H$6:$H$68,"Élevé",Risques!$L$6:$L$68,"<>Clos") | J10: =COUNTIF(Decisions!$F$6:$F$67,"Ouvert")+COUNTIF(Decisions!$F$6:$F$67,"En discussion") | L10: =COUNTIF(Jalons!$I$6:$I$22,"Dépassé")
B12: Tâches sans responsable | D12: Charge non assignée (j/p) | F12: Personnes actives dans l'équipe | H12: Charge restante (j/p) | J12: Semaines-personne restantes | L12: Risques ouverts (tous niveaux)
B13: =Equipe!$C$48 | D13: =Equipe!$C$49 | F13: =COUNTIF(Equipe!$H$6:$H$45,"Oui") | H13: =Modules!G26-Modules!H26 | J13: =(Modules!G26-Modules!H26)/5 | L13: =COUNTIF(Risques!$L$6:$L$68,"Ouvert")
B16: Avancement par version
B17: Version | C17: Objet | D17: Fin prévue | E17: Jours restants | F17: Charge (sem.) | G17: Avancement | H17: Tâches | I17: Faites | J17: Bloquées | K17: En retard | L17: État
B18: =Versions!B6 | C18: =Versions!C6 | D18: =Versions!E6 | E18: =Versions!F6 | F18: =Versions!H6 | G18: =Versions!J6 | H18: =Versions!K6 | I18: =Versions!L6 | J18: =Versions!N6 | K18: =Versions!O6 | L18: =Versions!P6
B19: =Versions!B7 | C19: =Versions!C7 | D19: =Versions!E7 | E19: =Versions!F7 | F19: =Versions!H7 | G19: =Versions!J7 | H19: =Versions!K7 | I19: =Versions!L7 | J19: =Versions!N7 | K19: =Versions!O7 | L19: =Versions!P7
B20: =Versions!B8 | C20: =Versions!C8 | D20: =Versions!E8 | E20: =Versions!F8 | F20: =Versions!H8 | G20: =Versions!J8 | H20: =Versions!K8 | I20: =Versions!L8 | J20: =Versions!N8 | K20: =Versions!O8 | L20: =Versions!P8
B21: =Versions!B9 | C21: =Versions!C9 | D21: =Versions!E9 | E21: =Versions!F9 | F21: =Versions!H9 | G21: =Versions!J9 | H21: =Versions!K9 | I21: =Versions!L9 | J21: =Versions!N9 | K21: =Versions!O9 | L21: =Versions!P9
B22: =Versions!B10 | C22: =Versions!C10 | D22: =Versions!E10 | E22: =Versions!F10 | F22: =Versions!H10 | G22: =Versions!J10 | H22: =Versions!K10 | I22: =Versions!L10 | J22: =Versions!N10 | K22: =Versions!O10 | L22: =Versions!P10
B25: Avancement par module
B26: Code | C26: Module | D26: Version cible | E26: Charge (j/p) | F26: Avancement | G26: Tâches | H26: Faites | I26: En cours | J26: Bloquées | K26: En retard | L26: État
B27: =Modules!B6 | C27: =Modules!C6 | D27: =Modules!F6 | E27: =Modules!G6 | F27: =Modules!I6 | G27: =Modules!J6 | H27: =Modules!K6 | I27: =Modules!L6 | J27: =Modules!M6 | K27: =Modules!N6 | L27: =Modules!O6
B28: =Modules!B7 | C28: =Modules!C7 | D28: =Modules!F7 | E28: =Modules!G7 | F28: =Modules!I7 | G28: =Modules!J7 | H28: =Modules!K7 | I28: =Modules!L7 | J28: =Modules!M7 | K28: =Modules!N7 | L28: =Modules!O7
B29: =Modules!B8 | C29: =Modules!C8 | D29: =Modules!F8 | E29: =Modules!G8 | F29: =Modules!I8 | G29: =Modules!J8 | H29: =Modules!K8 | I29: =Modules!L8 | J29: =Modules!M8 | K29: =Modules!N8 | L29: =Modules!O8
B30: =Modules!B9 | C30: =Modules!C9 | D30: =Modules!F9 | E30: =Modules!G9 | F30: =Modules!I9 | G30: =Modules!J9 | H30: =Modules!K9 | I30: =Modules!L9 | J30: =Modules!M9 | K30: =Modules!N9 | L30: =Modules!O9
B31: =Modules!B10 | C31: =Modules!C10 | D31: =Modules!F10 | E31: =Modules!G10 | F31: =Modules!I10 | G31: =Modules!J10 | H31: =Modules!K10 | I31: =Modules!L10 | J31: =Modules!M10 | K31: =Modules!N10 | L31: =Modules!O10
B32: =Modules!B11 | C32: =Modules!C11 | D32: =Modules!F11 | E32: =Modules!G11 | F32: =Modules!I11 | G32: =Modules!J11 | H32: =Modules!K11 | I32: =Modules!L11 | J32: =Modules!M11 | K32: =Modules!N11 | L32: =Modules!O11
B33: =Modules!B12 | C33: =Modules!C12 | D33: =Modules!F12 | E33: =Modules!G12 | F33: =Modules!I12 | G33: =Modules!J12 | H33: =Modules!K12 | I33: =Modules!L12 | J33: =Modules!M12 | K33: =Modules!N12 | L33: =Modules!O12
B34: =Modules!B13 | C34: =Modules!C13 | D34: =Modules!F13 | E34: =Modules!G13 | F34: =Modules!I13 | G34: =Modules!J13 | H34: =Modules!K13 | I34: =Modules!L13 | J34: =Modules!M13 | K34: =Modules!N13 | L34: =Modules!O13
B35: =Modules!B14 | C35: =Modules!C14 | D35: =Modules!F14 | E35: =Modules!G14 | F35: =Modules!I14 | G35: =Modules!J14 | H35: =Modules!K14 | I35: =Modules!L14 | J35: =Modules!M14 | K35: =Modules!N14 | L35: =Modules!O14
B36: =Modules!B15 | C36: =Modules!C15 | D36: =Modules!F15 | E36: =Modules!G15 | F36: =Modules!I15 | G36: =Modules!J15 | H36: =Modules!K15 | I36: =Modules!L15 | J36: =Modules!M15 | K36: =Modules!N15 | L36: =Modules!O15
B37: =Modules!B16 | C37: =Modules!C16 | D37: =Modules!F16 | E37: =Modules!G16 | F37: =Modules!I16 | G37: =Modules!J16 | H37: =Modules!K16 | I37: =Modules!L16 | J37: =Modules!M16 | K37: =Modules!N16 | L37: =Modules!O16
B38: =Modules!B17 | C38: =Modules!C17 | D38: =Modules!F17 | E38: =Modules!G17 | F38: =Modules!I17 | G38: =Modules!J17 | H38: =Modules!K17 | I38: =Modules!L17 | J38: =Modules!M17 | K38: =Modules!N17 | L38: =Modules!O17
... B46: =Modules!B25 | C46: =Modules!C25 | D46: =Modules!F25 | E46: =Modules!G25 | F46: =Modules!I25 | G46: =Modules!J25 | H46: =Modules!K25 | I46: =Modules!L25 | J46: =Modules!M25 | K46: =Modules!N25 | L46: =Modules!O25
B49: Prochain jalon | D49: =IFERROR(INDEX(Jalons!$C$6:$C$22,MATCH(MIN(Jalons!$J$6:$J$22),Jalons!$J$6:$J$22,0)),"Aucun") | J49: =IFERROR(MIN(Jalons!$J$6:$J$22),"")
B50: Jalons des 30 prochains jours | D50: =COUNTIFS(Jalons!$E$6:$E$22,">="&TODAY(),Jalons!$E$6:$E$22,"<="&(TODAY()+30),Jalons!$F$6:$F$22,"<>Atteint")
B53: Charge par personne (équipe inscrite)
B54: Nom | C54: Rôle | D54: Actif | E54: Tâches | F54: Charge (j/p) | G54: Réalisé (j/p) | H54: Avancement | I54: En cours | J54: Bloquées | K54: En retard | L54: Restant (j/p)
B55: =IF(Equipe!B6="","",Equipe!B6) | C55: =IF(Equipe!B6="","",Equipe!C6) | D55: =IF(Equipe!B6="","",Equipe!H6) | E55: =IF(Equipe!B6="","",Equipe!I6) | F55: =IF(Equipe!B6="","",Equipe!J6) | G55: =IF(Equipe!B6="","",Equipe!K6) | H55: =IF(Equipe!B6="","",Equipe!L6) | I55: =IF(Equipe!B6="","",Equipe!M6) | J55: =IF(Equipe!B6="","",Equipe!N6) | K55: =IF(Equipe!B6="","",Equipe!O6) | L55: =IF(Equipe!B6="","",Equipe!Q6)
B56: =IF(Equipe!B7="","",Equipe!B7) | C56: =IF(Equipe!B7="","",Equipe!C7) | D56: =IF(Equipe!B7="","",Equipe!H7) | E56: =IF(Equipe!B7="","",Equipe!I7) | F56: =IF(Equipe!B7="","",Equipe!J7) | G56: =IF(Equipe!B7="","",Equipe!K7) | H56: =IF(Equipe!B7="","",Equipe!L7) | I56: =IF(Equipe!B7="","",Equipe!M7) | J56: =IF(Equipe!B7="","",Equipe!N7) | K56: =IF(Equipe!B7="","",Equipe!O7) | L56: =IF(Equipe!B7="","",Equipe!Q7)
B57: =IF(Equipe!B8="","",Equipe!B8) | C57: =IF(Equipe!B8="","",Equipe!C8) | D57: =IF(Equipe!B8="","",Equipe!H8) | E57: =IF(Equipe!B8="","",Equipe!I8) | F57: =IF(Equipe!B8="","",Equipe!J8) | G57: =IF(Equipe!B8="","",Equipe!K8) | H57: =IF(Equipe!B8="","",Equipe!L8) | I57: =IF(Equipe!B8="","",Equipe!M8) | J57: =IF(Equipe!B8="","",Equipe!N8) | K57: =IF(Equipe!B8="","",Equipe!O8) | L57: =IF(Equipe!B8="","",Equipe!Q8)
B58: =IF(Equipe!B9="","",Equipe!B9) | C58: =IF(Equipe!B9="","",Equipe!C9) | D58: =IF(Equipe!B9="","",Equipe!H9) | E58: =IF(Equipe!B9="","",Equipe!I9) | F58: =IF(Equipe!B9="","",Equipe!J9) | G58: =IF(Equipe!B9="","",Equipe!K9) | H58: =IF(Equipe!B9="","",Equipe!L9) | I58: =IF(Equipe!B9="","",Equipe!M9) | J58: =IF(Equipe!B9="","",Equipe!N9) | K58: =IF(Equipe!B9="","",Equipe!O9) | L58: =IF(Equipe!B9="","",Equipe!Q9)
B59: =IF(Equipe!B10="","",Equipe!B10) | C59: =IF(Equipe!B10="","",Equipe!C10) | D59: =IF(Equipe!B10="","",Equipe!H10) | E59: =IF(Equipe!B10="","",Equipe!I10) | F59: =IF(Equipe!B10="","",Equipe!J10) | G59: =IF(Equipe!B10="","",Equipe!K10) | H59: =IF(Equipe!B10="","",Equipe!L10) | I59: =IF(Equipe!B10="","",Equipe!M10) | J59: =IF(Equipe!B10="","",Equipe!N10) | K59: =IF(Equipe!B10="","",Equipe!O10) | L59: =IF(Equipe!B10="","",Equipe!Q10)
...

Sheet Presentation
B2: DealPME : présentation du projet
B3: Place de marché de transmission et reprise de PME en Afrique francophone (zone OHADA), pilote Togo, en partenariat avec la CCI-Togo.
B5: 1. Le projet en quelques lignes
B6: DealPME est une infrastructure de confiance pour la transmission et la reprise de PME : elle vérifie les acteurs, prépare les dossiers, met en relation sous confidentialité contrôlée, sécurise la divulgation d'information et orchestre la transaction avec des professionnels. DealPME est un fournisseur logiciel : elle ne valorise pas, ne certifie pas, ne détient pas de fonds et n'est jamais partie à la transaction. La certification Deal-Ready est une décision souveraine et nominative de la CCI-Togo.
B7: Signature de marque : « Là où les entreprises changent de mains. »
B9: 2. Documents de référence et autorité
B10: Document | C10: Rôle | D10: Statut retenu
B11: Cahier des charges v0 approuvé (54 p., 25/06/2026) | C11: Spécification technique et juridique, ancrée AUSCGIE / AUDCG / AUPCAP, vendeurs locaux réels | D11: Autorité principale
B12: Référentiel de processus P04 à P25 (50 p., v1.0, contractuel CCI-Togo) | C12: 22 processus opposables, RACI, contrôles, indicateurs ; dérive directement du v0 | D12: Autorité opérationnelle
B13: Note investisseurs et partenaires (28 p., 26/06/2026) | C13: Thèse, marché, monétisation, feuille de route | D13: Contexte stratégique
B14: Services Blueprint v5.0 | C14: Vision générique (escrow, valorisation automatique, KYC biométrique, hub courtiers) non retrouvée dans le v0 ni le référentiel | D14: Non retenu
B15: Master Developer Handoff V3.1 (12 cas, 24 scénarios, 6 Skills) | C15: Corpus de référence exécutable : maquettes et fixtures servant d'oracle de test, pas de code de production | D15: Socle de conception à porter en production
B17: 3. Socle réglementaire qui gouverne tout le reste
B18: Bifurcation des types de cession : chaque dossier est typé dès l'origine ASSET_DEAL (fonds de commerce, librement commercialisable) ou SHARE_DEAL (titres, cercle fermé obligatoire). La forme juridique de la cible est vérifiée au RCCM.
B19: Regulatory Perimeter Service (RPS) : service indépendant qui applique trois paliers de divulgation. T0 : existence (secteur, région, taille). T1 : teaser anonymisé, jamais de prix ni d'identité. T2 : identité, prix et data room, uniquement après NDA. Compteur de divulgation par personne, plafond de cercle (défaut 50), filtre de communication, journal append-only haché. L'admission n'est jamais automatique.
B20: Dix portes de conformité (G1 à G10) doivent être fermées avant tout lancement commercial : déclaration IPDCP, transfert transfrontalier, prestataire de signature qualifié, revues juridiques, avis écrit sur le RPS, audit du texte d'interface, recalcul de la rétrocession, DPO nommé, pentest indépendant.
B21: 4. Pipeline transactionnel
B22: Compte vérifié > Qualifié > Admis (RPS) > NDA signé > T2 autorisé > Data room et Q&R > LOI et audit d'acquisition > Réalisation documentée. Chaque état est un sur-ensemble strict du précédent ; aucune étape ne peut être sautée sans règle documentée.
B23: 5. Intégrations réelles retenues par le v0
B24: Besoin | C24: Vendeurs retenus | D24: Note
B25: Mobile money | C25: CinetPay, PayDunya, Hub2, PayGate Global, Gozem Pay | D25: Rails réels : T-Money, Flooz, Gozem Money ; pas de carte bancaire par défaut
B26: Signature électronique | C26: Prestataire togolais accrédité ARCEP (PSC) | D26: Présomption légale de fiabilité, critère décisif
B27: Vérification d'identité | C27: Capture documentaire, revue humaine, OTP | D27: Aucune biométrie en v0
B28: Registre des entreprises | C28: CFE / RCCM | D28: Si aucune API : échange de fichier supervisé
B29: Archivage de preuve | C29: PSAE accrédité | D29: Valeur probante du NDA
B30: Événements et rendez-vous virtuels | C30: Remo.co | D30: Connecteur externe pour Deal-Connect et Guichet Diaspora
B31: Fiscalité | C31: Partenaire tiers à confirmer | D31: Le nom TaxeFacile n'apparaît que dans le blueprint v5
B33: 6. Exigences transverses
B34: Domaine | C34: Exigence
B35: Disponibilité | C35: 99,5 % mensuel, obligation de résultat contractuelle ; RPO 1 h, RTO 4 h ; priorités P1 à P4 avec délais
B36: Capacité pilote | C36: 2 000 comptes, 300 sessions concurrentes, 200 deals actifs, 20 000 documents ; test de charge à 2x ; ne pas sur-construire
B37: Sécurité | C37: TLS 1.3, AES-256, chiffrement applicatif des champs CONFIDENTIAL_DEAL, séparation VDR / marketplace, idempotence des webhooks, pentest
B38: Localisation | C38: Français langue source, formats FCFA sans décimale, termes OHADA jamais traduits, dates DD/MM/YYYY
B39: Ingénierie | C39: Monorepo apps/ et packages/, RPS déployé séparément, REST /v1, UUIDv7, montants en entier XOF, pagination par curseur
B41: 7. Hors périmètre v0 (à ne pas construire maintenant)
B42: Élément | C42: Statut | D42: Raison
B43: Deal-Pay et séquestre (escrow) | C43: Hors périmètre v0 | D43: Frontière d'intégration partenaire licencié désactivée ; avenant requis
B44: Valorisation algorithmique automatique | C44: Hors périmètre v0 | D44: Le v0 interdit toute fourchette présentée comme un avis DealPME
B45: Certification automatique / score de readiness | C45: Hors périmètre v0 | D45: Décision nominative CCI-Togo obligatoire
B46: KYC biométrique | C46: Différé (P2) | D46: Activable après autorisation IPDCP, sous drapeau fonctionnel
...

Sheet Feuille_de_route
B2: Feuille de route V1 à V5
B3: Détail de chaque version. Les charges et avancements par lot sont calculés depuis l'onglet Taches.
B5: V1 Premier produit : cessions d'actifs, espace CCI-Togo, Deal-Ready, démonstration du blocage RPS, Deal-Connect via Remo.co
B6: Début prévu | C6: Fin prévue | D6: Charge (j/p) | E6: Charge (sem.-pers.) | F6: Avancement | G6: État | H6: Semaines calendaires | I6: ETP requis à pleine cadence
B7: =Versions!D6 | C7: =Versions!E6 | D7: =Versions!G6 | E7: =Versions!H6 | F7: =Versions!J6 | G7: =Versions!P6 | H7: =ROUND((Versions!E6-Versions!D6)/7,1) | I7: =IFERROR(ROUND(Versions!H6/((Versions!E6-Versions!D6)/7),1),0)
B8: Premier produit de démonstration, à données synthétiques, pour faire comprendre le fonctionnement de DealPME. Cessions d'actifs uniquement, plus une démonstration maquettée du blocage RPS. La CCI-Togo confirme l'adhésion et décide seule de la certification.
B9: Inclus | F9: Exclu ou reporté
B10: + Authentification et rôles : cédant, investisseur, agent CCI-Togo, administrateur | F10: - Circuit RPS réel : admission humaine, compteur, plafond, journal réglementaire (V2)
B11: + Espace CCI-Togo : confirmation d'adhésion, vérification RCCM/CFE, décision de certification nominative | F11: - Data room chiffrée, filigranée, révocable et Q&R (V2)
B12: + Pass Transmission : constitution du dossier cédant | F12: - Moteur d'honoraires et rétrocession CCI (V3)
B13: + Marketplace de cessions d'actifs : recherche et mise en relation simple | F13: - Alerte & Rebond, billetterie et sponsoring Deal-Connect, rendez-vous mutuels, rapport post-événement, profil diaspora complet (V4)
B14: + Évaluation financière sommaire et indicative
B15: + Badge Deal-Ready affiché, workflow porté par la CCI-Togo
B16: + Démonstration maquettée du blocage RPS (bannière de nullité, scénario scripté)
B17: + Deal-Connect via Remo.co : événements, inscriptions avec consentement, lien d'accès unique, présence par webhook
B18: + Guichet Diaspora léger : demande de rendez-vous avec avis transfrontalier, entretien vidéo Remo après confirmation humaine
B19: + Lot Sécurité : RLS effective, anti-force-brute, MFA officiers et administrateurs, chiffrement applicatif, en-têtes, idempotence et signatures de webhooks, revue interne
B21: Lot | C21: Charge (j/p) | D21: Réalisé (j/p) | E21: Avancement | F21: Tâches | G21: Complétées | H21: Bloquées | I21: En retard
B22: Fondations | C22: =SUMIFS(Taches!$M$6:$M$325,Taches!$C$6:$C$325,"V1",Taches!$E$6:$E$325,$B22) | D22: =SUMIFS(Taches!$N$6:$N$325,Taches!$C$6:$C$325,"V1",Taches!$E$6:$E$325,$B22) | E22: =IF(C22=0,0,D22/C22) | F22: =COUNTIFS(Taches!$C$6:$C$325,"V1",Taches!$E$6:$E$325,$B22,Taches!$J$6:$J$325,"<>Abandonnée",Taches!$B$6:$B$325,"<>") | G22: =COUNTIFS(Taches!$C$6:$C$325,"V1",Taches!$E$6:$E$325,$B22,Taches!$J$6:$J$325,"Complétée") | H22: =COUNTIFS(Taches!$C$6:$C$325,"V1",Taches!$E$6:$E$325,$B22,Taches!$J$6:$J$325,"Bloquée") | I22: =COUNTIFS(Taches!$C$6:$C$325,"V1",Taches!$E$6:$E$325,$B22,Taches!$U$6:$U$325,"En retard")
B23: Auth et rôles | C23: =SUMIFS(Taches!$M$6:$M$325,Taches!$C$6:$C$325,"V1",Taches!$E$6:$E$325,$B23) | D23: =SUMIFS(Taches!$N$6:$N$325,Taches!$C$6:$C$325,"V1",Taches!$E$6:$E$325,$B23) | E23: =IF(C23=0,0,D23/C23) | F23: =COUNTIFS(Taches!$C$6:$C$325,"V1",Taches!$E$6:$E$325,$B23,Taches!$J$6:$J$325,"<>Abandonnée",Taches!$B$6:$B$325,"<>") | G23: =COUNTIFS(Taches!$C$6:$C$325,"V1",Taches!$E$6:$E$325,$B23,Taches!$J$6:$J$325,"Complétée") | H23: =COUNTIFS(Taches!$C$6:$C$325,"V1",Taches!$E$6:$E$325,$B23,Taches!$J$6:$J$325,"Bloquée") | I23: =COUNTIFS(Taches!$C$6:$C$325,"V1",Taches!$E$6:$E$325,$B23,Taches!$U$6:$U$325,"En retard")
B24: Espace CCI-Togo | C24: =SUMIFS(Taches!$M$6:$M$325,Taches!$C$6:$C$325,"V1",Taches!$E$6:$E$325,$B24) | D24: =SUMIFS(Taches!$N$6:$N$325,Taches!$C$6:$C$325,"V1",Taches!$E$6:$E$325,$B24) | E24: =IF(C24=0,0,D24/C24) | F24: =COUNTIFS(Taches!$C$6:$C$325,"V1",Taches!$E$6:$E$325,$B24,Taches!$J$6:$J$325,"<>Abandonnée",Taches!$B$6:$B$325,"<>") | G24: =COUNTIFS(Taches!$C$6:$C$325,"V1",Taches!$E$6:$E$325,$B24,Taches!$J$6:$J$325,"Complétée") | H24: =COUNTIFS(Taches!$C$6:$C$325,"V1",Taches!$E$6:$E$325,$B24,Taches!$J$6:$J$325,"Bloquée") | I24: =COUNTIFS(Taches!$C$6:$C$325,"V1",Taches!$E$6:$E$325,$B24,Taches!$U$6:$U$325,"En retard")
B25: Deal-Ready | C25: =SUMIFS(Taches!$M$6:$M$325,Taches!$C$6:$C$325,"V1",Taches!$E$6:$E$325,$B25) | D25: =SUMIFS(Taches!$N$6:$N$325,Taches!$C$6:$C$325,"V1",Taches!$E$6:$E$325,$B25) | E25: =IF(C25=0,0,D25/C25) | F25: =COUNTIFS(Taches!$C$6:$C$325,"V1",Taches!$E$6:$E$325,$B25,Taches!$J$6:$J$325,"<>Abandonnée",Taches!$B$6:$B$325,"<>") | G25: =COUNTIFS(Taches!$C$6:$C$325,"V1",Taches!$E$6:$E$325,$B25,Taches!$J$6:$J$325,"Complétée") | H25: =COUNTIFS(Taches!$C$6:$C$325,"V1",Taches!$E$6:$E$325,$B25,Taches!$J$6:$J$325,"Bloquée") | I25: =COUNTIFS(Taches!$C$6:$C$325,"V1",Taches!$E$6:$E$325,$B25,Taches!$U$6:$U$325,"En retard")
B26: Dossier cédant | C26: =SUMIFS(Taches!$M$6:$M$325,Taches!$C$6:$C$325,"V1",Taches!$E$6:$E$325,$B26) | D26: =SUMIFS(Taches!$N$6:$N$325,Taches!$C$6:$C$325,"V1",Taches!$E$6:$E$325,$B26) | E26: =IF(C26=0,0,D26/C26) | F26: =COUNTIFS(Taches!$C$6:$C$325,"V1",Taches!$E$6:$E$325,$B26,Taches!$J$6:$J$325,"<>Abandonnée",Taches!$B$6:$B$325,"<>") | G26: =COUNTIFS(Taches!$C$6:$C$325,"V1",Taches!$E$6:$E$325,$B26,Taches!$J$6:$J$325,"Complétée") | H26: =COUNTIFS(Taches!$C$6:$C$325,"V1",Taches!$E$6:$E$325,$B26,Taches!$J$6:$J$325,"Bloquée") | I26: =COUNTIFS(Taches!$C$6:$C$325,"V1",Taches!$E$6:$E$325,$B26,Taches!$U$6:$U$325,"En retard")
B27: Marketplace actifs | C27: =SUMIFS(Taches!$M$6:$M$325,Taches!$C$6:$C$325,"V1",Taches!$E$6:$E$325,$B27) | D27: =SUMIFS(Taches!$N$6:$N$325,Taches!$C$6:$C$325,"V1",Taches!$E$6:$E$325,$B27) | E27: =IF(C27=0,0,D27/C27) | F27: =COUNTIFS(Taches!$C$6:$C$325,"V1",Taches!$E$6:$E$325,$B27,Taches!$J$6:$J$325,"<>Abandonnée",Taches!$B$6:$B$325,"<>") | G27: =COUNTIFS(Taches!$C$6:$C$325,"V1",Taches!$E$6:$E$325,$B27,Taches!$J$6:$J$325,"Complétée") | H27: =COUNTIFS(Taches!$C$6:$C$325,"V1",Taches!$E$6:$E$325,$B27,Taches!$J$6:$J$325,"Bloquée") | I27: =COUNTIFS(Taches!$C$6:$C$325,"V1",Taches!$E$6:$E$325,$B27,Taches!$U$6:$U$325,"En retard")
B28: Évaluation indicative | C28: =SUMIFS(Taches!$M$6:$M$325,Taches!$C$6:$C$325,"V1",Taches!$E$6:$E$325,$B28) | D28: =SUMIFS(Taches!$N$6:$N$325,Taches!$C$6:$C$325,"V1",Taches!$E$6:$E$325,$B28) | E28: =IF(C28=0,0,D28/C28) | F28: =COUNTIFS(Taches!$C$6:$C$325,"V1",Taches!$E$6:$E$325,$B28,Taches!$J$6:$J$325,"<>Abandonnée",Taches!$B$6:$B$325,"<>") | G28: =COUNTIFS(Taches!$C$6:$C$325,"V1",Taches!$E$6:$E$325,$B28,Taches!$J$6:$J$325,"Complétée") | H28: =COUNTIFS(Taches!$C$6:$C$325,"V1",Taches!$E$6:$E$325,$B28,Taches!$J$6:$J$325,"Bloquée") | I28: =COUNTIFS(Taches!$C$6:$C$325,"V1",Taches!$E$6:$E$325,$B28,Taches!$U$6:$U$325,"En retard")
B29: Démonstration RPS | C29: =SUMIFS(Taches!$M$6:$M$325,Taches!$C$6:$C$325,"V1",Taches!$E$6:$E$325,$B29) | D29: =SUMIFS(Taches!$N$6:$N$325,Taches!$C$6:$C$325,"V1",Taches!$E$6:$E$325,$B29) | E29: =IF(C29=0,0,D29/C29) | F29: =COUNTIFS(Taches!$C$6:$C$325,"V1",Taches!$E$6:$E$325,$B29,Taches!$J$6:$J$325,"<>Abandonnée",Taches!$B$6:$B$325,"<>") | G29: =COUNTIFS(Taches!$C$6:$C$325,"V1",Taches!$E$6:$E$325,$B29,Taches!$J$6:$J$325,"Complétée") | H29: =COUNTIFS(Taches!$C$6:$C$325,"V1",Taches!$E$6:$E$325,$B29,Taches!$J$6:$J$325,"Bloquée") | I29: =COUNTIFS(Taches!$C$6:$C$325,"V1",Taches!$E$6:$E$325,$B29,Taches!$U$6:$U$325,"En retard")
B30: Deal-Connect (Remo) | C30: =SUMIFS(Taches!$M$6:$M$325,Taches!$C$6:$C$325,"V1",Taches!$E$6:$E$325,$B30) | D30: =SUMIFS(Taches!$N$6:$N$325,Taches!$C$6:$C$325,"V1",Taches!$E$6:$E$325,$B30) | E30: =IF(C30=0,0,D30/C30) | F30: =COUNTIFS(Taches!$C$6:$C$325,"V1",Taches!$E$6:$E$325,$B30,Taches!$J$6:$J$325,"<>Abandonnée",Taches!$B$6:$B$325,"<>") | G30: =COUNTIFS(Taches!$C$6:$C$325,"V1",Taches!$E$6:$E$325,$B30,Taches!$J$6:$J$325,"Complétée") | H30: =COUNTIFS(Taches!$C$6:$C$325,"V1",Taches!$E$6:$E$325,$B30,Taches!$J$6:$J$325,"Bloquée") | I30: =COUNTIFS(Taches!$C$6:$C$325,"V1",Taches!$E$6:$E$325,$B30,Taches!$U$6:$U$325,"En retard")
B31: Sécurité | C31: =SUMIFS(Taches!$M$6:$M$325,Taches!$C$6:$C$325,"V1",Taches!$E$6:$E$325,$B31) | D31: =SUMIFS(Taches!$N$6:$N$325,Taches!$C$6:$C$325,"V1",Taches!$E$6:$E$325,$B31) | E31: =IF(C31=0,0,D31/C31) | F31: =COUNTIFS(Taches!$C$6:$C$325,"V1",Taches!$E$6:$E$325,$B31,Taches!$J$6:$J$325,"<>Abandonnée",Taches!$B$6:$B$325,"<>") | G31: =COUNTIFS(Taches!$C$6:$C$325,"V1",Taches!$E$6:$E$325,$B31,Taches!$J$6:$J$325,"Complétée") | H31: =COUNTIFS(Taches!$C$6:$C$325,"V1",Taches!$E$6:$E$325,$B31,Taches!$J$6:$J$325,"Bloquée") | I31: =COUNTIFS(Taches!$C$6:$C$325,"V1",Taches!$E$6:$E$325,$B31,Taches!$U$6:$U$325,"En retard")
B32: Frontend et design | C32: =SUMIFS(Taches!$M$6:$M$325,Taches!$C$6:$C$325,"V1",Taches!$E$6:$E$325,$B32) | D32: =SUMIFS(Taches!$N$6:$N$325,Taches!$C$6:$C$325,"V1",Taches!$E$6:$E$325,$B32) | E32: =IF(C32=0,0,D32/C32) | F32: =COUNTIFS(Taches!$C$6:$C$325,"V1",Taches!$E$6:$E$325,$B32,Taches!$J$6:$J$325,"<>Abandonnée",Taches!$B$6:$B$325,"<>") | G32: =COUNTIFS(Taches!$C$6:$C$325,"V1",Taches!$E$6:$E$325,$B32,Taches!$J$6:$J$325,"Complétée") | H32: =COUNTIFS(Taches!$C$6:$C$325,"V1",Taches!$E$6:$E$325,$B32,Taches!$J$6:$J$325,"Bloquée") | I32: =COUNTIFS(Taches!$C$6:$C$325,"V1",Taches!$E$6:$E$325,$B32,Taches!$U$6:$U$325,"En retard")
B33: QA et livraison | C33: =SUMIFS(Taches!$M$6:$M$325,Taches!$C$6:$C$325,"V1",Taches!$E$6:$E$325,$B33) | D33: =SUMIFS(Taches!$N$6:$N$325,Taches!$C$6:$C$325,"V1",Taches!$E$6:$E$325,$B33) | E33: =IF(C33=0,0,D33/C33) | F33: =COUNTIFS(Taches!$C$6:$C$325,"V1",Taches!$E$6:$E$325,$B33,Taches!$J$6:$J$325,"<>Abandonnée",Taches!$B$6:$B$325,"<>") | G33: =COUNTIFS(Taches!$C$6:$C$325,"V1",Taches!$E$6:$E$325,$B33,Taches!$J$6:$J$325,"Complétée") | H33: =COUNTIFS(Taches!$C$6:$C$325,"V1",Taches!$E$6:$E$325,$B33,Taches!$J$6:$J$325,"Bloquée") | I33: =COUNTIFS(Taches!$C$6:$C$325,"V1",Taches!$E$6:$E$325,$B33,Taches!$U$6:$U$325,"En retard")
B34: Total V1 | C34: =SUM(C22:C33) | D34: =SUM(D22:D33) | E34: =IF(C34=0,0,D34/C34) | F34: =SUM(F22:F33) | G34: =SUM(G22:G33) | H34: =SUM(H22:H33) | I34: =SUM(I22:I33)
B36: Prérequis
B37: Équipe de développement confirmée (5 à 6 profils) ; réponse sur l'API CFE/RCCM ; designer UI/UX confirmé.
B38: Décision ou règle
B39: La démonstration RPS fait partie de V1. Sans équipe à 5 ou 6 profils, la démonstration RPS est le premier lot à retirer, avant le matching automatisé.
B42: V2 Cession de titres en cercle restreint (RPS réel), signature électronique, data room et Q&R
B43: Début prévu | C43: Fin prévue | D43: Charge (j/p) | E43: Charge (sem.-pers.) | F43: Avancement | G43: État | H43: Semaines calendaires | I43: ETP requis à pleine cadence
B44: =Versions!D7 | C44: =Versions!E7 | D44: =Versions!G7 | E44: =Versions!H7 | F44: =Versions!J7 | G44: =Versions!P7 | H44: =ROUND((Versions!E7-Versions!D7)/7,1) | I44: =IFERROR(ROUND(Versions!H7/((Versions!E7-Versions!D7)/7),1),0)
B45: Le cœur du différenciateur produit : le moteur RPS complet pour les cessions de titres et la data room. Prérequis à toute diligence réelle.
B46: Inclus | F46: Exclu ou reporté
...

Sheet Guide
B2: Mode d'emploi du classeur
B5: Principe | C5: L'onglet Taches est la seule source de vérité. Tout le reste (Modules, Versions, Processus, Jalons, Tableau de bord, Gantt) se recalcule automatiquement à partir des tâches.
B6: Mettre à jour une tâche | C6: Changer le Statut (liste déroulante). 'Complétée' = 100 %. Choisir le Responsable dans la liste des personnes inscrites dans l'onglet Equipe. Pour une tâche 'En cours', saisir un pourcentage dans '% saisi' si l'on veut être précis ; sinon 25 % s'applique par défaut (90 % pour 'En revue').
B7: Ajouter une tâche | C7: Écrire sur la première ligne vide de l'onglet Taches en renseignant au minimum ID, Version, Module, Tâche, Charge et Statut. Les formules des colonnes grises sont déjà en place jusqu'à la ligne 325. Le Gantt et tous les totaux la prennent en compte immédiatement.
B8: Abandonner une tâche | C8: Mettre le statut 'Abandonnée' : la tâche sort des totaux de charge sans être supprimée (traçabilité).
B9: Codes couleur | C9: Cellules jaune pâle : à saisir. Cellules grises : calculées, ne pas modifier. Statuts colorés automatiquement (vert complétée, ambre en cours, rouge bloquée).
B10: Modules | C10: Avancement pondéré par la charge des tâches du module. Colonnes Responsable et Commentaire à saisir. Les éléments hors périmètre v0 sont listés pour mémoire, sans tâche.
B11: Versions | C11: Les dates de début et de fin se saisissent ici. L'état passe automatiquement à 'En dépassement' si la date de fin est passée sans 100 %.
B12: Jalons | C12: Saisir la date cible et le statut. La colonne Alerte signale 'Dépassé' ou 'Cette semaine'. Le tableau de bord affiche le prochain jalon non atteint.
B13: Risques | C13: Saisir probabilité et impact de 1 à 5. Le score et le niveau se calculent. Passer le statut à 'Clos' quand le risque est levé.
B14: Securite | C14: Registre des constats de sécurité : chaque ligne renvoie à la tâche qui la traite ; le statut et l'avancement se lisent automatiquement. Un report vers une version ultérieure doit être justifié et accompagné d'une mitigation.
B15: Decisions | C15: Toute demande de changement de périmètre s'inscrit ici avant d'être traduite en tâches. Statut : Ouvert, En discussion, Tranché.
B16: Gantt | C16: Barres hebdomadaires calculées depuis 'Début prévu' et 'Fin prévue' de chaque tâche. Modifier les dates dans Taches, pas dans le Gantt. La colonne de la semaine courante est surlignée.
... B19: Partage | C19: Ce classeur est conçu pour être le point de rencontre de tous les acteurs : les développeurs mettent à jour Taches, la CCI-Togo et M. Bruno lisent le Tableau de bord, les Jalons et les Decisions.

Sheet Taches
B2: Tâches détaillées
B3: Source unique de vérité. Colonnes jaunes : à saisir. Colonnes grises : calculées, ne pas modifier. Filtrer avec les en-têtes.
B5: ID | C5: Version | D5: Module | E5: Lot | F5: Tâche | G5: Critère de fin | H5: Charge (j/p) | I5: Priorité | J5: Statut | K5: % saisi (optionnel) | L5: Avancement | M5: Charge retenue | N5: Charge réalisée | O5: Responsable | P5: Début prévu | Q5: Fin prévue | R5: Fin réelle | S5: Dépendances | T5: Bloquant | U5: Retard | V5: Commentaire
B6: V1-001 | C6: V1 | D6: TRV | E6: Fondations | F6: Dépôt monorepo (apps/, packages/), conventions de code, CI de base | G6: Pipeline CI vert sur une branche vide, lint et tests exécutés | H6: 3 | I6: Haute | J6: Complétée | L6: =IF($B6="","",IF(J6="Complétée",1,IF(J6="Abandonnée",0,IF(K6<>"",K6,IFERROR(VLOOKUP(J6,Parametres!$B$6:$C$12,2,FALSE),0))))) | M6: =IF($B6="","",IF(J6="Abandonnée",0,H6)) | N6: =IF($B6="","",M6*L6) | O6: Abdou-Raouf | P6: 46268 | Q6: 46273 | R6: 46274 | T6: Non | U6: =IF($B6="","",IF(AND(J6<>"Complétée",J6<>"Abandonnée",Q6<>"",TODAY()>Q6),"En retard",""))
B7: V1-002 | C7: V1 | D7: TRV | E7: Fondations | F7: Environnements dev / staging, gestion des secrets, déploiement de base | G7: Déploiement automatique de staging depuis la branche principale | H7: 4 | I7: Haute | J7: En cours | K7: 0.7 | L7: =IF($B7="","",IF(J7="Complétée",1,IF(J7="Abandonnée",0,IF(K7<>"",K7,IFERROR(VLOOKUP(J7,Parametres!$B$6:$C$12,2,FALSE),0))))) | M7: =IF($B7="","",IF(J7="Abandonnée",0,H7)) | N7: =IF($B7="","",M7*L7) | O7: Abdou-Raouf | P7: 46268 | Q7: 46274 | T7: Non | U7: =IF($B7="","",IF(AND(J7<>"Complétée",J7<>"Abandonnée",Q7<>"",TODAY()>Q7),"En retard",""))
B8: V1-003 | C8: V1 | D8: FOND | E8: Fondations | F8: Modèle de données socle : Organisation, User, Person, Company | G8: Migrations appliquées, classification de chaque champ renseignée | H8: 4 | I8: Haute | J8: Complétée | L8: =IF($B8="","",IF(J8="Complétée",1,IF(J8="Abandonnée",0,IF(K8<>"",K8,IFERROR(VLOOKUP(J8,Parametres!$B$6:$C$12,2,FALSE),0))))) | M8: =IF($B8="","",IF(J8="Abandonnée",0,H8)) | N8: =IF($B8="","",M8*L8) | O8: Abdou-Raouf | P8: 46269 | Q8: 46275 | R8: 46274 | T8: Non | U8: =IF($B8="","",IF(AND(J8<>"Complétée",J8<>"Abandonnée",Q8<>"",TODAY()>Q8),"En retard",""))
B9: V1-004 | C9: V1 | D9: FOND | E9: Fondations | F9: Modèle Deal et AssetDealDetail, typage ASSET_DEAL / SHARE_DEAL immuable | G9: Impossible de modifier dealType après création (test négatif) | H9: 4 | I9: Haute | J9: Complétée | L9: =IF($B9="","",IF(J9="Complétée",1,IF(J9="Abandonnée",0,IF(K9<>"",K9,IFERROR(VLOOKUP(J9,Parametres!$B$6:$C$12,2,FALSE),0))))) | M9: =IF($B9="","",IF(J9="Abandonnée",0,H9)) | N9: =IF($B9="","",M9*L9) | O9: Abdou-Raouf | P9: 46270 | Q9: 46276 | R9: 46275 | T9: Non | U9: =IF($B9="","",IF(AND(J9<>"Complétée",J9<>"Abandonnée",Q9<>"",TODAY()>Q9),"En retard",""))
B10: V1-005 | C10: V1 | D10: FOND | E10: Fondations | F10: Classification des champs (PUBLIC, INTERNAL, PERSONAL, CONFIDENTIAL_DEAL) dans les migrations | G10: Chaque colonne porte sa classification en commentaire de migration | H10: 2 | I10: Haute | J10: En cours | K10: 0.7 | L10: =IF($B10="","",IF(J10="Complétée",1,IF(J10="Abandonnée",0,IF(K10<>"",K10,IFERROR(VLOOKUP(J10,Parametres!$B$6:$C$12,2,FALSE),0))))) | M10: =IF($B10="","",IF(J10="Abandonnée",0,H10)) | N10: =IF($B10="","",M10*L10) | O10: Abdou-Raouf | P10: 46270 | Q10: 46273 | T10: Non | U10: =IF($B10="","",IF(AND(J10<>"Complétée",J10<>"Abandonnée",Q10<>"",TODAY()>Q10),"En retard",""))
B11: V1-006 | C11: V1 | D11: FOND | E11: Fondations | F11: Enregistrement d'attribution immuable à la création de compte (canal, campagne, référence CCI) | G11: Attribution non modifiable après création (test négatif) | H11: 2 | I11: Haute | J11: Complétée | L11: =IF($B11="","",IF(J11="Complétée",1,IF(J11="Abandonnée",0,IF(K11<>"",K11,IFERROR(VLOOKUP(J11,Parametres!$B$6:$C$12,2,FALSE),0))))) | M11: =IF($B11="","",IF(J11="Abandonnée",0,H11)) | N11: =IF($B11="","",M11*L11) | O11: Abdou-Raouf | P11: 46270 | Q11: 46273 | R11: 46275 | T11: Non | U11: =IF($B11="","",IF(AND(J11<>"Complétée",J11<>"Abandonnée",Q11<>"",TODAY()>Q11),"En retard",""))
B12: V1-007 | C12: V1 | D12: FOND | E12: Fondations | F12: Journal DealEvent et machine à états du deal (version réduite V1) | G12: Transition invalide renvoie 409, chaque transition journalisée | H12: 4 | I12: Haute | J12: Complétée | L12: =IF($B12="","",IF(J12="Complétée",1,IF(J12="Abandonnée",0,IF(K12<>"",K12,IFERROR(VLOOKUP(J12,Parametres!$B$6:$C$12,2,FALSE),0))))) | M12: =IF($B12="","",IF(J12="Abandonnée",0,H12)) | N12: =IF($B12="","",M12*L12) | O12: Abdou-Raouf | P12: 46271 | Q12: 46277 | R12: 46274 | T12: Non | U12: =IF($B12="","",IF(AND(J12<>"Complétée",J12<>"Abandonnée",Q12<>"",TODAY()>Q12),"En retard",""))
B13: V1-008 | C13: V1 | D13: TRV | E13: Fondations | F13: Socle i18n français-source, formats FCFA (entier, sans décimale), dates, typographie | G13: Aucune chaîne anglaise dans l'interface, montants en XOF entiers | H13: 3 | I13: Moyenne | J13: En cours | K13: 0.6 | L13: =IF($B13="","",IF(J13="Complétée",1,IF(J13="Abandonnée",0,IF(K13<>"",K13,IFERROR(VLOOKUP(J13,Parametres!$B$6:$C$12,2,FALSE),0))))) | M13: =IF($B13="","",IF(J13="Abandonnée",0,H13)) | N13: =IF($B13="","",M13*L13) | O13: Abdou-Raouf | P13: 46271 | Q13: 46276 | T13: Non | U13: =IF($B13="","",IF(AND(J13<>"Complétée",J13<>"Abandonnée",Q13<>"",TODAY()>Q13),"En retard",""))
B14: V1-009 | C14: V1 | D14: OPS | E14: Fondations | F14: Supervision et journaux applicatifs de base | G14: Journaux centralisés, alerte sur erreur 5xx | H14: 3 | I14: Moyenne | J14: À faire | L14: =IF($B14="","",IF(J14="Complétée",1,IF(J14="Abandonnée",0,IF(K14<>"",K14,IFERROR(VLOOKUP(J14,Parametres!$B$6:$C$12,2,FALSE),0))))) | M14: =IF($B14="","",IF(J14="Abandonnée",0,H14)) | N14: =IF($B14="","",M14*L14) | P14: 46272 | Q14: 46277 | T14: Non | U14: =IF($B14="","",IF(AND(J14<>"Complétée",J14<>"Abandonnée",Q14<>"",TODAY()>Q14),"En retard",""))
B15: V1-010 | C15: V1 | D15: OPS | E15: Fondations | F15: Sauvegardes de base de la base de données | G15: Sauvegarde quotidienne, restauration testée une fois | H15: 2 | I15: Moyenne | J15: À faire | L15: =IF($B15="","",IF(J15="Complétée",1,IF(J15="Abandonnée",0,IF(K15<>"",K15,IFERROR(VLOOKUP(J15,Parametres!$B$6:$C$12,2,FALSE),0))))) | M15: =IF($B15="","",IF(J15="Abandonnée",0,H15)) | N15: =IF($B15="","",M15*L15) | P15: 46272 | Q15: 46275 | T15: Non | U15: =IF($B15="","",IF(AND(J15<>"Complétée",J15<>"Abandonnée",Q15<>"",TODAY()>Q15),"En retard",""))
B16: V1-011 | C16: V1 | D16: OPS | E16: Sécurité | F16: RLS effective : rôle applicatif sans contournement, contexte app.organisation_id et app.roles par transaction | G16: Test négatif : un cédant ne lit pas le dossier d'un autre cédant | H16: 4 | I16: Haute | J16: Complétée | L16: =IF($B16="","",IF(J16="Complétée",1,IF(J16="Abandonnée",0,IF(K16<>"",K16,IFERROR(VLOOKUP(J16,Parametres!$B$6:$C$12,2,FALSE),0))))) | M16: =IF($B16="","",IF(J16="Abandonnée",0,H16)) | N16: =IF($B16="","",M16*L16) | O16: Abdou-Raouf | P16: 46272 | Q16: 46278 | R16: 46275 | T16: Oui | U16: =IF($B16="","",IF(AND(J16<>"Complétée",J16<>"Abandonnée",Q16<>"",TODAY()>Q16),"En retard",""))
B17: V1-012 | C17: V1 | D17: OPS | E17: Sécurité | F17: Anti-force-brute : limitation de débit par IP et par compte, verrouillage progressif, journal des échecs | G17: Cinquième échec en une minute renvoie 429 et laisse une trace | H17: 2 | I17: Haute | J17: Complétée | L17: =IF($B17="","",IF(J17="Complétée",1,IF(J17="Abandonnée",0,IF(K17<>"",K17,IFERROR(VLOOKUP(J17,Parametres!$B$6:$C$12,2,FALSE),0))))) | M17: =IF($B17="","",IF(J17="Abandonnée",0,H17)) | N17: =IF($B17="","",M17*L17) | O17: Abdou-Raouf | P17: 46273 | Q17: 46276 | R17: 46275 | T17: Non | U17: =IF($B17="","",IF(AND(J17<>"Complétée",J17<>"Abandonnée",Q17<>"",TODAY()>Q17),"En retard",""))
B18: V1-013 | C18: V1 | D18: OPS | E18: Sécurité | F18: Vérification email, MFA obligatoire pour les officiers CCI-Togo et les administrateurs, liaison OTP | G18: Officier sans second facteur ne peut pas certifier | H18: 3 | I18: Haute | J18: Complétée | L18: =IF($B18="","",IF(J18="Complétée",1,IF(J18="Abandonnée",0,IF(K18<>"",K18,IFERROR(VLOOKUP(J18,Parametres!$B$6:$C$12,2,FALSE),0))))) | M18: =IF($B18="","",IF(J18="Abandonnée",0,H18)) | N18: =IF($B18="","",M18*L18) | O18: Abdou-Raouf | P18: 46273 | Q18: 46278 | R18: 46275 | S18: OTP SMS | T18: Non | U18: =IF($B18="","",IF(AND(J18<>"Complétée",J18<>"Abandonnée",Q18<>"",TODAY()>Q18),"En retard",""))
B19: V1-014 | C19: V1 | D19: OPS | E19: Sécurité | F19: Chiffrement applicatif des champs CONFIDENTIAL_DEAL, clé gérée hors base, rotation documentée | G19: Prix illisible dans un dump de la base | H19: 3 | I19: Haute | J19: Complétée | L19: =IF($B19="","",IF(J19="Complétée",1,IF(J19="Abandonnée",0,IF(K19<>"",K19,IFERROR(VLOOKUP(J19,Parametres!$B$6:$C$12,2,FALSE),0))))) | M19: =IF($B19="","",IF(J19="Abandonnée",0,H19)) | N19: =IF($B19="","",M19*L19) | O19: Abdou-Raouf | P19: 46274 | Q19: 46279 | R19: 46275 | T19: Non | U19: =IF($B19="","",IF(AND(J19<>"Complétée",J19<>"Abandonnée",Q19<>"",TODAY()>Q19),"En retard",""))
B20: V1-015 | C20: V1 | D20: OPS | E20: Sécurité | F20: En-têtes de sécurité HTTP, CORS strict, cookies sécurisés, taille maximale des corps de requête | G20: Scan d'en-têtes sans constat, origine inconnue refusée | H20: 1 | I20: Moyenne | J20: Complétée | L20: =IF($B20="","",IF(J20="Complétée",1,IF(J20="Abandonnée",0,IF(K20<>"",K20,IFERROR(VLOOKUP(J20,Parametres!$B$6:$C$12,2,FALSE),0))))) | M20: =IF($B20="","",IF(J20="Abandonnée",0,H20)) | N20: =IF($B20="","",M20*L20) | O20: Abdou-Raouf | P20: 46274 | Q20: 46276 | R20: 46275 | T20: Non | U20: =IF($B20="","",IF(AND(J20<>"Complétée",J20<>"Abandonnée",Q20<>"",TODAY()>Q20),"En retard",""))
B21: V1-016 | C21: V1 | D21: OPS | E21: Sécurité | F21: Idempotence persistée en base et vérification de signature HMAC sur tous les webhooks | G21: Rejeu d'un webhook sans double effet ; signature invalide rejetée | H21: 2 | I21: Haute | J21: Complétée | L21: =IF($B21="","",IF(J21="Complétée",1,IF(J21="Abandonnée",0,IF(K21<>"",K21,IFERROR(VLOOKUP(J21,Parametres!$B$6:$C$12,2,FALSE),0))))) | M21: =IF($B21="","",IF(J21="Abandonnée",0,H21)) | N21: =IF($B21="","",M21*L21) | O21: Abdou-Raouf | P21: 46274 | Q21: 46277 | R21: 46275 | T21: Non | U21: =IF($B21="","",IF(AND(J21<>"Complétée",J21<>"Abandonnée",Q21<>"",TODAY()>Q21),"En retard",""))
B22: V1-017 | C22: V1 | D22: OPS | E22: Sécurité | F22: Revue de sécurité interne (liste de contrôle v0 : paliers, URL pré-signées, compteur RPS) et scan de dépendances bloquant en CI | G22: Rapport de revue archivé, CI rouge sur vulnérabilité critique | H22: 3 | I22: Haute | J22: À faire | L22: =IF($B22="","",IF(J22="Complétée",1,IF(J22="Abandonnée",0,IF(K22<>"",K22,IFERROR(VLOOKUP(J22,Parametres!$B$6:$C$12,2,FALSE),0))))) | M22: =IF($B22="","",IF(J22="Abandonnée",0,H22)) | N22: =IF($B22="","",M22*L22) | P22: 46274 | Q22: 46279 | T22: Non | U22: =IF($B22="","",IF(AND(J22<>"Complétée",J22<>"Abandonnée",Q22<>"",TODAY()>Q22),"En retard",""))
B23: V1-018 | C23: V1 | D23: OPS | E23: Sécurité | F23: Mots de passe de démonstration uniques par compte, jeu de démonstration interdit hors environnement local | G23: Le chargement refuse de s'exécuter si NODE_ENV n'est pas development | H23: 1 | I23: Moyenne | J23: Complétée | L23: =IF($B23="","",IF(J23="Complétée",1,IF(J23="Abandonnée",0,IF(K23<>"",K23,IFERROR(VLOOKUP(J23,Parametres!$B$6:$C$12,2,FALSE),0))))) | M23: =IF($B23="","",IF(J23="Abandonnée",0,H23)) | N23: =IF($B23="","",M23*L23) | O23: Abdou-Raouf | P23: 46275 | Q23: 46277 | R23: 46275 | T23: Non | U23: =IF($B23="","",IF(AND(J23<>"Complétée",J23<>"Abandonnée",Q23<>"",TODAY()>Q23),"En retard",""))
B24: V1-019 | C24: V1 | D24: IDN | E24: Auth et rôles | F24: Inscription email + mot de passe (Argon2id), vérification email | G24: Compte créé, email vérifié, mot de passe jamais en clair | H24: 3 | I24: Haute | J24: En cours | K24: 0.7 | L24: =IF($B24="","",IF(J24="Complétée",1,IF(J24="Abandonnée",0,IF(K24<>"",K24,IFERROR(VLOOKUP(J24,Parametres!$B$6:$C$12,2,FALSE),0))))) | M24: =IF($B24="","",IF(J24="Abandonnée",0,H24)) | N24: =IF($B24="","",M24*L24) | O24: Abdou-Raouf | P24: 46275 | Q24: 46280 | T24: Non | U24: =IF($B24="","",IF(AND(J24<>"Complétée",J24<>"Abandonnée",Q24<>"",TODAY()>Q24),"En retard",""))
B25: V1-020 | C25: V1 | D25: IDN | E25: Auth et rôles | F25: OTP SMS (intégration fournisseur SMS) | G25: Code reçu et validé en moins de 60 s en test | H25: 3 | I25: Haute | J25: En cours | K25: 0.6 | L25: =IF($B25="","",IF(J25="Complétée",1,IF(J25="Abandonnée",0,IF(K25<>"",K25,IFERROR(VLOOKUP(J25,Parametres!$B$6:$C$12,2,FALSE),0))))) | M25: =IF($B25="","",IF(J25="Abandonnée",0,H25)) | N25: =IF($B25="","",M25*L25) | O25: Abdou-Raouf | P25: 46275 | Q25: 46280 | T25: Non | U25: =IF($B25="","",IF(AND(J25<>"Complétée",J25<>"Abandonnée",Q25<>"",TODAY()>Q25),"En retard",""))
B26: V1-021 | C26: V1 | D26: IDN | E26: Auth et rôles | F26: Rôles et permissions évalués côté serveur (cédant, investisseur, agent CCI-Togo, admin) | G26: Chaque endpoint refuse un rôle non autorisé (tests négatifs) | H26: 4 | I26: Haute | J26: Complétée | L26: =IF($B26="","",IF(J26="Complétée",1,IF(J26="Abandonnée",0,IF(K26<>"",K26,IFERROR(VLOOKUP(J26,Parametres!$B$6:$C$12,2,FALSE),0))))) | M26: =IF($B26="","",IF(J26="Abandonnée",0,H26)) | N26: =IF($B26="","",M26*L26) | O26: Abdou-Raouf | P26: 46276 | Q26: 46282 | R26: 46275 | T26: Non | U26: =IF($B26="","",IF(AND(J26<>"Complétée",J26<>"Abandonnée",Q26<>"",TODAY()>Q26),"En retard",""))
B27: V1-022 | C27: V1 | D27: IDN | E27: Auth et rôles | F27: Gestion de session : expiration, liste des appareils, révocation à distance | G27: Session révoquée inutilisable immédiatement | H27: 2 | I27: Moyenne | J27: En cours | K27: 0.7 | L27: =IF($B27="","",IF(J27="Complétée",1,IF(J27="Abandonnée",0,IF(K27<>"",K27,IFERROR(VLOOKUP(J27,Parametres!$B$6:$C$12,2,FALSE),0))))) | M27: =IF($B27="","",IF(J27="Abandonnée",0,H27)) | N27: =IF($B27="","",M27*L27) | O27: Abdou-Raouf | P27: 46276 | Q27: 46279 | T27: Non | U27: =IF($B27="","",IF(AND(J27<>"Complétée",J27<>"Abandonnée",Q27<>"",TODAY()>Q27),"En retard",""))
B28: V1-023 | C28: V1 | D28: IDN | E28: Auth et rôles | F28: Consentements séparés (CGU, confidentialité, marketing) | G28: Trois cases distinctes, marketing non pré-coché | H28: 2 | I28: Moyenne | J28: Complétée | L28: =IF($B28="","",IF(J28="Complétée",1,IF(J28="Abandonnée",0,IF(K28<>"",K28,IFERROR(VLOOKUP(J28,Parametres!$B$6:$C$12,2,FALSE),0))))) | M28: =IF($B28="","",IF(J28="Abandonnée",0,H28)) | N28: =IF($B28="","",M28*L28) | O28: Abdou-Raouf | P28: 46277 | Q28: 46280 | R28: 46274 | T28: Non | U28: =IF($B28="","",IF(AND(J28<>"Complétée",J28<>"Abandonnée",Q28<>"",TODAY()>Q28),"En retard",""))
B29: V1-024 | C29: V1 | D29: IDN | E29: Auth et rôles | F29: Paliers d'abonnement : modèle et entitlements (sans paiement en V1) | G29: Entitlement résolu depuis un service unique versionné | H29: 4 | I29: Moyenne | J29: En cours | K29: 0.5 | L29: =IF($B29="","",IF(J29="Complétée",1,IF(J29="Abandonnée",0,IF(K29<>"",K29,IFERROR(VLOOKUP(J29,Parametres!$B$6:$C$12,2,FALSE),0))))) | M29: =IF($B29="","",IF(J29="Abandonnée",0,H29)) | N29: =IF($B29="","",M29*L29) | O29: Abdou-Raouf | P29: 46277 | Q29: 46283 | T29: Non | U29: =IF($B29="","",IF(AND(J29<>"Complétée",J29<>"Abandonnée",Q29<>"",TODAY()>Q29),"En retard",""))
B30: V1-025 | C30: V1 | D30: IDN | E30: Auth et rôles | F30: Écrans authentification (connexion, inscription, OTP, profil) | G30: Parcours complet sur mobile et desktop | H30: 4 | I30: Haute | J30: À faire | L30: =IF($B30="","",IF(J30="Complétée",1,IF(J30="Abandonnée",0,IF(K30<>"",K30,IFERROR(VLOOKUP(J30,Parametres!$B$6:$C$12,2,FALSE),0))))) | M30: =IF($B30="","",IF(J30="Abandonnée",0,H30)) | N30: =IF($B30="","",M30*L30) | P30: 46278 | Q30: 46284 | T30: Non | U30: =IF($B30="","",IF(AND(J30<>"Complétée",J30<>"Abandonnée",Q30<>"",TODAY()>Q30),"En retard",""))
B31: V1-026 | C31: V1 | D31: GOV | E31: Espace CCI-Togo | F31: Workflow de confirmation d'adhésion (demande, décision, référence stockée) | G31: Seule la référence de confirmation est stockée, jamais la base des membres | H31: 4 | I31: Haute | J31: En cours | K31: 0.8 | L31: =IF($B31="","",IF(J31="Complétée",1,IF(J31="Abandonnée",0,IF(K31<>"",K31,IFERROR(VLOOKUP(J31,Parametres!$B$6:$C$12,2,FALSE),0))))) | M31: =IF($B31="","",IF(J31="Abandonnée",0,H31)) | N31: =IF($B31="","",M31*L31) | O31: Abdou-Raouf | P31: 46278 | Q31: 46284 | T31: Non | U31: =IF($B31="","",IF(AND(J31<>"Complétée",J31<>"Abandonnée",Q31<>"",TODAY()>Q31),"En retard",""))
B32: V1-027 | C32: V1 | D32: GOV | E32: Espace CCI-Togo | F32: Vérification RCCM / CFE : adaptateur (API si disponible, sinon saisie manuelle supervisée) | G32: Source et horodatage de vérification stockés | H32: 5 | I32: Haute | J32: En cours | K32: 0.7 | L32: =IF($B32="","",IF(J32="Complétée",1,IF(J32="Abandonnée",0,IF(K32<>"",K32,IFERROR(VLOOKUP(J32,Parametres!$B$6:$C$12,2,FALSE),0))))) | M32: =IF($B32="","",IF(J32="Abandonnée",0,H32)) | N32: =IF($B32="","",M32*L32) | O32: Abdou-Raouf | P32: 46279 | Q32: 46286 | S32: Réponse sur l'API CFE/RCCM | T32: Oui | U32: =IF($B32="","",IF(AND(J32<>"Complétée",J32<>"Abandonnée",Q32<>"",TODAY()>Q32),"En retard",""))
B33: V1-028 | C33: V1 | D33: GOV | E33: Espace CCI-Togo | F33: RegistryRecord stocké séparément des données déclarées par le cédant | G33: Deux tables distinctes, aucune fusion à l'affichage | H33: 2 | I33: Haute | J33: Complétée | L33: =IF($B33="","",IF(J33="Complétée",1,IF(J33="Abandonnée",0,IF(K33<>"",K33,IFERROR(VLOOKUP(J33,Parametres!$B$6:$C$12,2,FALSE),0))))) | M33: =IF($B33="","",IF(J33="Abandonnée",0,H33)) | N33: =IF($B33="","",M33*L33) | O33: Abdou-Raouf | P33: 46279 | Q33: 46282 | R33: 46274 | T33: Non | U33: =IF($B33="","",IF(AND(J33<>"Complétée",J33<>"Abandonnée",Q33<>"",TODAY()>Q33),"En retard",""))
B34: V1-029 | C34: V1 | D34: GOV | E34: Espace CCI-Togo | F34: Tableau de bord institutionnel agrégé (version minimale) | G34: Aucune vue sur le contenu confidentiel d'un dossier | H34: 3 | I34: Moyenne | J34: À faire | L34: =IF($B34="","",IF(J34="Complétée",1,IF(J34="Abandonnée",0,IF(K34<>"",K34,IFERROR(VLOOKUP(J34,Parametres!$B$6:$C$12,2,FALSE),0))))) | M34: =IF($B34="","",IF(J34="Abandonnée",0,H34)) | N34: =IF($B34="","",M34*L34) | P34: 46280 | Q34: 46285 | T34: Non | U34: =IF($B34="","",IF(AND(J34<>"Complétée",J34<>"Abandonnée",Q34<>"",TODAY()>Q34),"En retard",""))
B35: V1-030 | C35: V1 | D35: GOV | E35: Espace CCI-Togo | F35: Écrans console CCI-Togo | G35: Rôles et journal d'audit séparés du back-office plateforme | H35: 5 | I35: Haute | J35: À faire | L35: =IF($B35="","",IF(J35="Complétée",1,IF(J35="Abandonnée",0,IF(K35<>"",K35,IFERROR(VLOOKUP(J35,Parametres!$B$6:$C$12,2,FALSE),0))))) | M35: =IF($B35="","",IF(J35="Abandonnée",0,H35)) | N35: =IF($B35="","",M35*L35) | P35: 46280 | Q35: 46287 | T35: Non | U35: =IF($B35="","",IF(AND(J35<>"Complétée",J35<>"Abandonnée",Q35<>"",TODAY()>Q35),"En retard",""))
B36: V1-031 | C36: V1 | D36: CCI | E36: Deal-Ready | F36: Modèle Certification : portée, décision, officier, expiration, révocation | G36: Chaque décision porte un officier nommé | H36: 2 | I36: Haute | J36: Complétée | L36: =IF($B36="","",IF(J36="Complétée",1,IF(J36="Abandonnée",0,IF(K36<>"",K36,IFERROR(VLOOKUP(J36,Parametres!$B$6:$C$12,2,FALSE),0))))) | M36: =IF($B36="","",IF(J36="Abandonnée",0,H36)) | N36: =IF($B36="","",M36*L36) | O36: Abdou-Raouf | P36: 46281 | Q36: 46284 | R36: 46274 | T36: Non | U36: =IF($B36="","",IF(AND(J36<>"Complétée",J36<>"Abandonnée",Q36<>"",TODAY()>Q36),"En retard",""))
B37: V1-032 | C37: V1 | D37: CCI | E37: Deal-Ready | F37: Workflow de décision nominative (octroi, refus, retrait) et déclaration de conflit d'intérêts | G37: Octroi automatique impossible par construction (test négatif) | H37: 4 | I37: Haute | J37: Complétée | L37: =IF($B37="","",IF(J37="Complétée",1,IF(J37="Abandonnée",0,IF(K37<>"",K37,IFERROR(VLOOKUP(J37,Parametres!$B$6:$C$12,2,FALSE),0))))) | M37: =IF($B37="","",IF(J37="Abandonnée",0,H37)) | N37: =IF($B37="","",M37*L37) | O37: Abdou-Raouf | P37: 46281 | Q37: 46287 | R37: 46275 | T37: Non | U37: =IF($B37="","",IF(AND(J37<>"Complétée",J37<>"Abandonnée",Q37<>"",TODAY()>Q37),"En retard",""))
B38: V1-033 | C38: V1 | D38: CCI | E38: Deal-Ready | F38: Checklist Deal-Ready et pièces attendues | G38: Liste des manques visible par l'entreprise | H38: 3 | I38: Moyenne | J38: À faire | L38: =IF($B38="","",IF(J38="Complétée",1,IF(J38="Abandonnée",0,IF(K38<>"",K38,IFERROR(VLOOKUP(J38,Parametres!$B$6:$C$12,2,FALSE),0))))) | M38: =IF($B38="","",IF(J38="Abandonnée",0,H38)) | N38: =IF($B38="","",M38*L38) | P38: 46282 | Q38: 46287 | T38: Non | U38: =IF($B38="","",IF(AND(J38<>"Complétée",J38<>"Abandonnée",Q38<>"",TODAY()>Q38),"En retard",""))
B39: V1-034 | C39: V1 | D39: CCI | E39: Deal-Ready | F39: Écrans côté entreprise : demande, suivi de remédiation | G39: Statut et pièces manquantes visibles | H39: 4 | I39: Moyenne | J39: À faire | L39: =IF($B39="","",IF(J39="Complétée",1,IF(J39="Abandonnée",0,IF(K39<>"",K39,IFERROR(VLOOKUP(J39,Parametres!$B$6:$C$12,2,FALSE),0))))) | M39: =IF($B39="","",IF(J39="Abandonnée",0,H39)) | N39: =IF($B39="","",M39*L39) | P39: 46282 | Q39: 46288 | T39: Non | U39: =IF($B39="","",IF(AND(J39<>"Complétée",J39<>"Abandonnée",Q39<>"",TODAY()>Q39),"En retard",""))
B40: V1-035 | C40: V1 | D40: CCI | E40: Deal-Ready | F40: Badge Deal-Ready : affichage avec périmètre et limites explicites | G40: Texte du badge précise ce qui est vérifié et ce qui ne l'est pas | H40: 2 | I40: Haute | J40: En cours | K40: 0.6 | L40: =IF($B40="","",IF(J40="Complétée",1,IF(J40="Abandonnée",0,IF(K40<>"",K40,IFERROR(VLOOKUP(J40,Parametres!$B$6:$C$12,2,FALSE),0))))) | M40: =IF($B40="","",IF(J40="Abandonnée",0,H40)) | N40: =IF($B40="","",M40*L40) | O40: Abdou-Raouf | P40: 46283 | Q40: 46286 | T40: Non | U40: =IF($B40="","",IF(AND(J40<>"Complétée",J40<>"Abandonnée",Q40<>"",TODAY()>Q40),"En retard",""))
B41: V1-036 | C41: V1 | D41: CCI | E41: Deal-Ready | F41: Journal d'audit des décisions de certification | G41: Chaque décision exportable avec horodatage et officier | H41: 2 | I41: Moyenne | J41: En cours | K41: 0.6 | L41: =IF($B41="","",IF(J41="Complétée",1,IF(J41="Abandonnée",0,IF(K41<>"",K41,IFERROR(VLOOKUP(J41,Parametres!$B$6:$C$12,2,FALSE),0))))) | M41: =IF($B41="","",IF(J41="Abandonnée",0,H41)) | N41: =IF($B41="","",M41*L41) | O41: Abdou-Raouf | P41: 46283 | Q41: 46286 | T41: Non | U41: =IF($B41="","",IF(AND(J41<>"Complétée",J41<>"Abandonnée",Q41<>"",TODAY()>Q41),"En retard",""))
B42: V1-037 | C42: V1 | D42: MKT | E42: Dossier cédant | F42: Assistant de constitution de dossier : étapes, branchement par type de cession dès l'étape 1 | G42: Parcours actif complet, branche titres présente mais bloquée en V1 | H42: 6 | I42: Haute | J42: En cours | K42: 0.15 | L42: =IF($B42="","",IF(J42="Complétée",1,IF(J42="Abandonnée",0,IF(K42<>"",K42,IFERROR(VLOOKUP(J42,Parametres!$B$6:$C$12,2,FALSE),0))))) | M42: =IF($B42="","",IF(J42="Abandonnée",0,H42)) | N42: =IF($B42="","",M42*L42) | O42: Abdou-Raouf | P42: 46283 | Q42: 46292 | T42: Non | U42: =IF($B42="","",IF(AND(J42<>"Complétée",J42<>"Abandonnée",Q42<>"",TODAY()>Q42),"En retard",""))
...

Sheet Equipe
B2: Équipe projet
B3: Chaque développeur s'inscrit ici (colonnes jaunes). Son nom devient alors sélectionnable dans la colonne Responsable de l'onglet Taches. Charges et avancement calculés.
B5: Nom complet | C5: Rôle | D5: Organisation | E5: Contact | F5: Disponibilité | G5: Arrivée | H5: Actif | I5: Tâches assignées | J5: Charge assignée (j/p) | K5: Charge réalisée (j/p) | L5: Avancement | M5: En cours | N5: Bloquées | O5: En retard | P5: Complétées | Q5: Charge restante (j/p) | R5: Commentaire
B6: Abdou-Raouf | C6: Chef de projet / architecte | D6: DealPME | F6: 1 | G6: 46274 | H6: Oui | I6: =IF($B6="","",COUNTIFS(Taches!$O$6:$O$325,$B6,Taches!$J$6:$J$325,"<>Abandonnée")) | J6: =IF($B6="","",SUMIF(Taches!$O$6:$O$325,$B6,Taches!$M$6:$M$325)) | K6: =IF($B6="","",SUMIF(Taches!$O$6:$O$325,$B6,Taches!$N$6:$N$325)) | L6: =IF(OR($B6="",J6=0),"",K6/J6) | M6: =IF($B6="","",COUNTIFS(Taches!$O$6:$O$325,$B6,Taches!$J$6:$J$325,"En cours")+COUNTIFS(Taches!$O$6:$O$325,$B6,Taches!$J$6:$J$325,"En revue")) | N6: =IF($B6="","",COUNTIFS(Taches!$O$6:$O$325,$B6,Taches!$J$6:$J$325,"Bloquée")) | O6: =IF($B6="","",COUNTIFS(Taches!$O$6:$O$325,$B6,Taches!$U$6:$U$325,"En retard")) | P6: =IF($B6="","",COUNTIFS(Taches!$O$6:$O$325,$B6,Taches!$J$6:$J$325,"Complétée")) | Q6: =IF($B6="","",J6-K6) | R6: Pilotage, architecture, revue de code
I7: =IF($B7="","",COUNTIFS(Taches!$O$6:$O$325,$B7,Taches!$J$6:$J$325,"<>Abandonnée")) | J7: =IF($B7="","",SUMIF(Taches!$O$6:$O$325,$B7,Taches!$M$6:$M$325)) | K7: =IF($B7="","",SUMIF(Taches!$O$6:$O$325,$B7,Taches!$N$6:$N$325)) | L7: =IF(OR($B7="",J7=0),"",K7/J7) | M7: =IF($B7="","",COUNTIFS(Taches!$O$6:$O$325,$B7,Taches!$J$6:$J$325,"En cours")+COUNTIFS(Taches!$O$6:$O$325,$B7,Taches!$J$6:$J$325,"En revue")) | N7: =IF($B7="","",COUNTIFS(Taches!$O$6:$O$325,$B7,Taches!$J$6:$J$325,"Bloquée")) | O7: =IF($B7="","",COUNTIFS(Taches!$O$6:$O$325,$B7,Taches!$U$6:$U$325,"En retard")) | P7: =IF($B7="","",COUNTIFS(Taches!$O$6:$O$325,$B7,Taches!$J$6:$J$325,"Complétée")) | Q7: =IF($B7="","",J7-K7)
I8: =IF($B8="","",COUNTIFS(Taches!$O$6:$O$325,$B8,Taches!$J$6:$J$325,"<>Abandonnée")) | J8: =IF($B8="","",SUMIF(Taches!$O$6:$O$325,$B8,Taches!$M$6:$M$325)) | K8: =IF($B8="","",SUMIF(Taches!$O$6:$O$325,$B8,Taches!$N$6:$N$325)) | L8: =IF(OR($B8="",J8=0),"",K8/J8) | M8: =IF($B8="","",COUNTIFS(Taches!$O$6:$O$325,$B8,Taches!$J$6:$J$325,"En cours")+COUNTIFS(Taches!$O$6:$O$325,$B8,Taches!$J$6:$J$325,"En revue")) | N8: =IF($B8="","",COUNTIFS(Taches!$O$6:$O$325,$B8,Taches!$J$6:$J$325,"Bloquée")) | O8: =IF($B8="","",COUNTIFS(Taches!$O$6:$O$325,$B8,Taches!$U$6:$U$325,"En retard")) | P8: =IF($B8="","",COUNTIFS(Taches!$O$6:$O$325,$B8,Taches!$J$6:$J$325,"Complétée")) | Q8: =IF($B8="","",J8-K8)
I9: =IF($B9="","",COUNTIFS(Taches!$O$6:$O$325,$B9,Taches!$J$6:$J$325,"<>Abandonnée")) | J9: =IF($B9="","",SUMIF(Taches!$O$6:$O$325,$B9,Taches!$M$6:$M$325)) | K9: =IF($B9="","",SUMIF(Taches!$O$6:$O$325,$B9,Taches!$N$6:$N$325)) | L9: =IF(OR($B9="",J9=0),"",K9/J9) | M9: =IF($B9="","",COUNTIFS(Taches!$O$6:$O$325,$B9,Taches!$J$6:$J$325,"En cours")+COUNTIFS(Taches!$O$6:$O$325,$B9,Taches!$J$6:$J$325,"En revue")) | N9: =IF($B9="","",COUNTIFS(Taches!$O$6:$O$325,$B9,Taches!$J$6:$J$325,"Bloquée")) | O9: =IF($B9="","",COUNTIFS(Taches!$O$6:$O$325,$B9,Taches!$U$6:$U$325,"En retard")) | P9: =IF($B9="","",COUNTIFS(Taches!$O$6:$O$325,$B9,Taches!$J$6:$J$325,"Complétée")) | Q9: =IF($B9="","",J9-K9)
I10: =IF($B10="","",COUNTIFS(Taches!$O$6:$O$325,$B10,Taches!$J$6:$J$325,"<>Abandonnée")) | J10: =IF($B10="","",SUMIF(Taches!$O$6:$O$325,$B10,Taches!$M$6:$M$325)) | K10: =IF($B10="","",SUMIF(Taches!$O$6:$O$325,$B10,Taches!$N$6:$N$325)) | L10: =IF(OR($B10="",J10=0),"",K10/J10) | M10: =IF($B10="","",COUNTIFS(Taches!$O$6:$O$325,$B10,Taches!$J$6:$J$325,"En cours")+COUNTIFS(Taches!$O$6:$O$325,$B10,Taches!$J$6:$J$325,"En revue")) | N10: =IF($B10="","",COUNTIFS(Taches!$O$6:$O$325,$B10,Taches!$J$6:$J$325,"Bloquée")) | O10: =IF($B10="","",COUNTIFS(Taches!$O$6:$O$325,$B10,Taches!$U$6:$U$325,"En retard")) | P10: =IF($B10="","",COUNTIFS(Taches!$O$6:$O$325,$B10,Taches!$J$6:$J$325,"Complétée")) | Q10: =IF($B10="","",J10-K10)
I11: =IF($B11="","",COUNTIFS(Taches!$O$6:$O$325,$B11,Taches!$J$6:$J$325,"<>Abandonnée")) | J11: =IF($B11="","",SUMIF(Taches!$O$6:$O$325,$B11,Taches!$M$6:$M$325)) | K11: =IF($B11="","",SUMIF(Taches!$O$6:$O$325,$B11,Taches!$N$6:$N$325)) | L11: =IF(OR($B11="",J11=0),"",K11/J11) | M11: =IF($B11="","",COUNTIFS(Taches!$O$6:$O$325,$B11,Taches!$J$6:$J$325,"En cours")+COUNTIFS(Taches!$O$6:$O$325,$B11,Taches!$J$6:$J$325,"En revue")) | N11: =IF($B11="","",COUNTIFS(Taches!$O$6:$O$325,$B11,Taches!$J$6:$J$325,"Bloquée")) | O11: =IF($B11="","",COUNTIFS(Taches!$O$6:$O$325,$B11,Taches!$U$6:$U$325,"En retard")) | P11: =IF($B11="","",COUNTIFS(Taches!$O$6:$O$325,$B11,Taches!$J$6:$J$325,"Complétée")) | Q11: =IF($B11="","",J11-K11)
I12: =IF($B12="","",COUNTIFS(Taches!$O$6:$O$325,$B12,Taches!$J$6:$J$325,"<>Abandonnée")) | J12: =IF($B12="","",SUMIF(Taches!$O$6:$O$325,$B12,Taches!$M$6:$M$325)) | K12: =IF($B12="","",SUMIF(Taches!$O$6:$O$325,$B12,Taches!$N$6:$N$325)) | L12: =IF(OR($B12="",J12=0),"",K12/J12) | M12: =IF($B12="","",COUNTIFS(Taches!$O$6:$O$325,$B12,Taches!$J$6:$J$325,"En cours")+COUNTIFS(Taches!$O$6:$O$325,$B12,Taches!$J$6:$J$325,"En revue")) | N12: =IF($B12="","",COUNTIFS(Taches!$O$6:$O$325,$B12,Taches!$J$6:$J$325,"Bloquée")) | O12: =IF($B12="","",COUNTIFS(Taches!$O$6:$O$325,$B12,Taches!$U$6:$U$325,"En retard")) | P12: =IF($B12="","",COUNTIFS(Taches!$O$6:$O$325,$B12,Taches!$J$6:$J$325,"Complétée")) | Q12: =IF($B12="","",J12-K12)
I13: =IF($B13="","",COUNTIFS(Taches!$O$6:$O$325,$B13,Taches!$J$6:$J$325,"<>Abandonnée")) | J13: =IF($B13="","",SUMIF(Taches!$O$6:$O$325,$B13,Taches!$M$6:$M$325)) | K13: =IF($B13="","",SUMIF(Taches!$O$6:$O$325,$B13,Taches!$N$6:$N$325)) | L13: =IF(OR($B13="",J13=0),"",K13/J13) | M13: =IF($B13="","",COUNTIFS(Taches!$O$6:$O$325,$B13,Taches!$J$6:$J$325,"En cours")+COUNTIFS(Taches!$O$6:$O$325,$B13,Taches!$J$6:$J$325,"En revue")) | N13: =IF($B13="","",COUNTIFS(Taches!$O$6:$O$325,$B13,Taches!$J$6:$J$325,"Bloquée")) | O13: =IF($B13="","",COUNTIFS(Taches!$O$6:$O$325,$B13,Taches!$U$6:$U$325,"En retard")) | P13: =IF($B13="","",COUNTIFS(Taches!$O$6:$O$325,$B13,Taches!$J$6:$J$325,"Complétée")) | Q13: =IF($B13="","",J13-K13)
I14: =IF($B14="","",COUNTIFS(Taches!$O$6:$O$325,$B14,Taches!$J$6:$J$325,"<>Abandonnée")) | J14: =IF($B14="","",SUMIF(Taches!$O$6:$O$325,$B14,Taches!$M$6:$M$325)) | K14: =IF($B14="","",SUMIF(Taches!$O$6:$O$325,$B14,Taches!$N$6:$N$325)) | L14: =IF(OR($B14="",J14=0),"",K14/J14) | M14: =IF($B14="","",COUNTIFS(Taches!$O$6:$O$325,$B14,Taches!$J$6:$J$325,"En cours")+COUNTIFS(Taches!$O$6:$O$325,$B14,Taches!$J$6:$J$325,"En revue")) | N14: =IF($B14="","",COUNTIFS(Taches!$O$6:$O$325,$B14,Taches!$J$6:$J$325,"Bloquée")) | O14: =IF($B14="","",COUNTIFS(Taches!$O$6:$O$325,$B14,Taches!$U$6:$U$325,"En retard")) | P14: =IF($B14="","",COUNTIFS(Taches!$O$6:$O$325,$B14,Taches!$J$6:$J$325,"Complétée")) | Q14: =IF($B14="","",J14-K14)
I15: =IF($B15="","",COUNTIFS(Taches!$O$6:$O$325,$B15,Taches!$J$6:$J$325,"<>Abandonnée")) | J15: =IF($B15="","",SUMIF(Taches!$O$6:$O$325,$B15,Taches!$M$6:$M$325)) | K15: =IF($B15="","",SUMIF(Taches!$O$6:$O$325,$B15,Taches!$N$6:$N$325)) | L15: =IF(OR($B15="",J15=0),"",K15/J15) | M15: =IF($B15="","",COUNTIFS(Taches!$O$6:$O$325,$B15,Taches!$J$6:$J$325,"En cours")+COUNTIFS(Taches!$O$6:$O$325,$B15,Taches!$J$6:$J$325,"En revue")) | N15: =IF($B15="","",COUNTIFS(Taches!$O$6:$O$325,$B15,Taches!$J$6:$J$325,"Bloquée")) | O15: =IF($B15="","",COUNTIFS(Taches!$O$6:$O$325,$B15,Taches!$U$6:$U$325,"En retard")) | P15: =IF($B15="","",COUNTIFS(Taches!$O$6:$O$325,$B15,Taches!$J$6:$J$325,"Complétée")) | Q15: =IF($B15="","",J15-K15)
I16: =IF($B16="","",COUNTIFS(Taches!$O$6:$O$325,$B16,Taches!$J$6:$J$325,"<>Abandonnée")) | J16: =IF($B16="","",SUMIF(Taches!$O$6:$O$325,$B16,Taches!$M$6:$M$325)) | K16: =IF($B16="","",SUMIF(Taches!$O$6:$O$325,$B16,Taches!$N$6:$N$325)) | L16: =IF(OR($B16="",J16=0),"",K16/J16) | M16: =IF($B16="","",COUNTIFS(Taches!$O$6:$O$325,$B16,Taches!$J$6:$J$325,"En cours")+COUNTIFS(Taches!$O$6:$O$325,$B16,Taches!$J$6:$J$325,"En revue")) | N16: =IF($B16="","",COUNTIFS(Taches!$O$6:$O$325,$B16,Taches!$J$6:$J$325,"Bloquée")) | O16: =IF($B16="","",COUNTIFS(Taches!$O$6:$O$325,$B16,Taches!$U$6:$U$325,"En retard")) | P16: =IF($B16="","",COUNTIFS(Taches!$O$6:$O$325,$B16,Taches!$J$6:$J$325,"Complétée")) | Q16: =IF($B16="","",J16-K16)
